2020-10-25 18:00:18,410 ERROR: Exception on /champselect [GET] [in e:\program files (x86)\microsoft visual studio\shared\python36_64\lib\site-packages\flask\app.py:1891]
Traceback (most recent call last):
  File "e:\program files (x86)\microsoft visual studio\shared\python36_64\lib\site-packages\flask\app.py", line 2446, in wsgi_app
    response = self.full_dispatch_request()
  File "e:\program files (x86)\microsoft visual studio\shared\python36_64\lib\site-packages\flask\app.py", line 1951, in full_dispatch_request
    rv = self.handle_user_exception(e)
  File "e:\program files (x86)\microsoft visual studio\shared\python36_64\lib\site-packages\flask\app.py", line 1820, in handle_user_exception
    reraise(exc_type, exc_value, tb)
  File "e:\program files (x86)\microsoft visual studio\shared\python36_64\lib\site-packages\flask\_compat.py", line 39, in reraise
    raise value
  File "e:\program files (x86)\microsoft visual studio\shared\python36_64\lib\site-packages\flask\app.py", line 1949, in full_dispatch_request
    rv = self.dispatch_request()
  File "e:\program files (x86)\microsoft visual studio\shared\python36_64\lib\site-packages\flask\app.py", line 1935, in dispatch_request
    return self.view_functions[rule.endpoint](**req.view_args)
  File "C:\Users\Fabian\Desktop\Hopdi\Prosjekter\bordplassering\app\routes.py", line 221, in found
    return render_template("index_flaskpage.html", obj=overView[identifier],user= current_user,allergiesList=allergyOverview)
KeyError: 'champselect'
2020-12-06 15:35:47,545 INFO: Microblog startup [in C:\Users\Fabian\Desktop\Hopland Digital\Prosjekter\bordplassering\app\__init__.py:73]
2020-12-06 16:02:44,529 INFO: Microblog startup [in C:\Users\Fabian\Desktop\Hopland Digital\Prosjekter\bordplassering\app\__init__.py:73]
2020-12-06 16:03:22,977 INFO: Microblog startup [in C:\Users\Fabian\Desktop\Hopland Digital\Prosjekter\bordplassering\app\__init__.py:73]
2020-12-06 16:11:47,302 INFO: Microblog startup [in C:\Users\Fabian\Desktop\Hopland Digital\Prosjekter\bordplassering\app\__init__.py:73]
2020-12-06 16:12:25,869 INFO: Microblog startup [in C:\Users\Fabian\Desktop\Hopland Digital\Prosjekter\bordplassering\app\__init__.py:73]
2020-12-06 16:13:02,802 INFO: Microblog startup [in C:\Users\Fabian\Desktop\Hopland Digital\Prosjekter\bordplassering\app\__init__.py:73]
2020-12-06 16:15:02,860 INFO: Microblog startup [in C:\Users\Fabian\Desktop\Hopland Digital\Prosjekter\bordplassering\app\__init__.py:73]
2020-12-06 16:20:22,451 INFO: Microblog startup [in C:\Users\Fabian\Desktop\Hopland Digital\Prosjekter\bordplassering\app\__init__.py:73]
2020-12-06 16:21:38,163 INFO: Microblog startup [in C:\Users\Fabian\Desktop\Hopland Digital\Prosjekter\bordplassering\app\__init__.py:73]
2020-12-06 16:22:30,525 INFO: Microblog startup [in C:\Users\Fabian\Desktop\Hopland Digital\Prosjekter\bordplassering\app\__init__.py:73]
2020-12-06 16:23:25,464 ERROR: Exception on /project/save/41f1cf3edd3b8328 [POST] [in E:\Program Files (x86)\Microsoft Visual Studio\Shared\Python36_64\lib\site-packages\flask\app.py:1891]
Traceback (most recent call last):
  File "E:\Program Files (x86)\Microsoft Visual Studio\Shared\Python36_64\lib\site-packages\sqlalchemy\engine\base.py", line 1244, in _execute_context
    cursor, statement, parameters, context
  File "E:\Program Files (x86)\Microsoft Visual Studio\Shared\Python36_64\lib\site-packages\sqlalchemy\engine\default.py", line 552, in do_execute
    cursor.execute(statement, parameters)
sqlite3.IntegrityError: UNIQUE constraint failed: projects.name

The above exception was the direct cause of the following exception:

Traceback (most recent call last):
  File "E:\Program Files (x86)\Microsoft Visual Studio\Shared\Python36_64\lib\site-packages\flask\app.py", line 2446, in wsgi_app
    response = self.full_dispatch_request()
  File "E:\Program Files (x86)\Microsoft Visual Studio\Shared\Python36_64\lib\site-packages\flask\app.py", line 1951, in full_dispatch_request
    rv = self.handle_user_exception(e)
  File "E:\Program Files (x86)\Microsoft Visual Studio\Shared\Python36_64\lib\site-packages\flask\app.py", line 1820, in handle_user_exception
    reraise(exc_type, exc_value, tb)
  File "E:\Program Files (x86)\Microsoft Visual Studio\Shared\Python36_64\lib\site-packages\flask\_compat.py", line 39, in reraise
    raise value
  File "E:\Program Files (x86)\Microsoft Visual Studio\Shared\Python36_64\lib\site-packages\flask\app.py", line 1949, in full_dispatch_request
    rv = self.dispatch_request()
  File "E:\Program Files (x86)\Microsoft Visual Studio\Shared\Python36_64\lib\site-packages\flask\app.py", line 1935, in dispatch_request
    return self.view_functions[rule.endpoint](**req.view_args)
  File "C:\Users\Fabian\Desktop\Hopland Digital\Prosjekter\bordplassering\app\routes.py", line 280, in saveProjectWithIdentifier
    db.session.commit()
  File "E:\Program Files (x86)\Microsoft Visual Studio\Shared\Python36_64\lib\site-packages\sqlalchemy\orm\scoping.py", line 162, in do
    return getattr(self.registry(), name)(*args, **kwargs)
  File "E:\Program Files (x86)\Microsoft Visual Studio\Shared\Python36_64\lib\site-packages\sqlalchemy\orm\session.py", line 1026, in commit
    self.transaction.commit()
  File "E:\Program Files (x86)\Microsoft Visual Studio\Shared\Python36_64\lib\site-packages\sqlalchemy\orm\session.py", line 493, in commit
    self._prepare_impl()
  File "E:\Program Files (x86)\Microsoft Visual Studio\Shared\Python36_64\lib\site-packages\sqlalchemy\orm\session.py", line 472, in _prepare_impl
    self.session.flush()
  File "E:\Program Files (x86)\Microsoft Visual Studio\Shared\Python36_64\lib\site-packages\sqlalchemy\orm\session.py", line 2451, in flush
    self._flush(objects)
  File "E:\Program Files (x86)\Microsoft Visual Studio\Shared\Python36_64\lib\site-packages\sqlalchemy\orm\session.py", line 2589, in _flush
    transaction.rollback(_capture_exception=True)
  File "E:\Program Files (x86)\Microsoft Visual Studio\Shared\Python36_64\lib\site-packages\sqlalchemy\util\langhelpers.py", line 68, in __exit__
    compat.reraise(exc_type, exc_value, exc_tb)
  File "E:\Program Files (x86)\Microsoft Visual Studio\Shared\Python36_64\lib\site-packages\sqlalchemy\util\compat.py", line 129, in reraise
    raise value
  File "E:\Program Files (x86)\Microsoft Visual Studio\Shared\Python36_64\lib\site-packages\sqlalchemy\orm\session.py", line 2549, in _flush
    flush_context.execute()
  File "E:\Program Files (x86)\Microsoft Visual Studio\Shared\Python36_64\lib\site-packages\sqlalchemy\orm\unitofwork.py", line 422, in execute
    rec.execute(self)
  File "E:\Program Files (x86)\Microsoft Visual Studio\Shared\Python36_64\lib\site-packages\sqlalchemy\orm\unitofwork.py", line 589, in execute
    uow,
  File "E:\Program Files (x86)\Microsoft Visual Studio\Shared\Python36_64\lib\site-packages\sqlalchemy\orm\persistence.py", line 245, in save_obj
    insert,
  File "E:\Program Files (x86)\Microsoft Visual Studio\Shared\Python36_64\lib\site-packages\sqlalchemy\orm\persistence.py", line 1120, in _emit_insert_statements
    statement, params
  File "E:\Program Files (x86)\Microsoft Visual Studio\Shared\Python36_64\lib\site-packages\sqlalchemy\engine\base.py", line 988, in execute
    return meth(self, multiparams, params)
  File "E:\Program Files (x86)\Microsoft Visual Studio\Shared\Python36_64\lib\site-packages\sqlalchemy\sql\elements.py", line 287, in _execute_on_connection
    return connection._execute_clauseelement(self, multiparams, params)
  File "E:\Program Files (x86)\Microsoft Visual Studio\Shared\Python36_64\lib\site-packages\sqlalchemy\engine\base.py", line 1107, in _execute_clauseelement
    distilled_params,
  File "E:\Program Files (x86)\Microsoft Visual Studio\Shared\Python36_64\lib\site-packages\sqlalchemy\engine\base.py", line 1248, in _execute_context
    e, statement, parameters, cursor, context
  File "E:\Program Files (x86)\Microsoft Visual Studio\Shared\Python36_64\lib\site-packages\sqlalchemy\engine\base.py", line 1466, in _handle_dbapi_exception
    util.raise_from_cause(sqlalchemy_exception, exc_info)
  File "E:\Program Files (x86)\Microsoft Visual Studio\Shared\Python36_64\lib\site-packages\sqlalchemy\util\compat.py", line 383, in raise_from_cause
    reraise(type(exception), exception, tb=exc_tb, cause=cause)
  File "E:\Program Files (x86)\Microsoft Visual Studio\Shared\Python36_64\lib\site-packages\sqlalchemy\util\compat.py", line 128, in reraise
    raise value.with_traceback(tb)
  File "E:\Program Files (x86)\Microsoft Visual Studio\Shared\Python36_64\lib\site-packages\sqlalchemy\engine\base.py", line 1244, in _execute_context
    cursor, statement, parameters, context
  File "E:\Program Files (x86)\Microsoft Visual Studio\Shared\Python36_64\lib\site-packages\sqlalchemy\engine\default.py", line 552, in do_execute
    cursor.execute(statement, parameters)
sqlalchemy.exc.IntegrityError: (sqlite3.IntegrityError) UNIQUE constraint failed: projects.name
[SQL: INSERT INTO projects (name, "projectLink", timestamp) VALUES (?, ?, ?)]
[parameters: ('St. Hallvardguttene konsert', '41f1cf3edd3b8328', '2020-12-06 15:23:25.463655')]
(Background on this error at: http://sqlalche.me/e/gkpj)
