2020-08-23 05:52:49,770 ERROR: Exception on /project/save/75a6fed5ce85870a [POST] [in E:\Program Files (x86)\Microsoft Visual Studio\Shared\Python36_64\lib\site-packages\flask\app.py:1891]
Traceback (most recent call last):
  File "E:\Program Files (x86)\Microsoft Visual Studio\Shared\Python36_64\lib\site-packages\flask\app.py", line 2446, in wsgi_app
    response = self.full_dispatch_request()
  File "E:\Program Files (x86)\Microsoft Visual Studio\Shared\Python36_64\lib\site-packages\flask\app.py", line 1951, in full_dispatch_request
    rv = self.handle_user_exception(e)
  File "E:\Program Files (x86)\Microsoft Visual Studio\Shared\Python36_64\lib\site-packages\flask\app.py", line 1820, in handle_user_exception
    reraise(exc_type, exc_value, tb)
  File "E:\Program Files (x86)\Microsoft Visual Studio\Shared\Python36_64\lib\site-packages\flask\_compat.py", line 39, in reraise
    raise value
  File "E:\Program Files (x86)\Microsoft Visual Studio\Shared\Python36_64\lib\site-packages\flask\app.py", line 1949, in full_dispatch_request
    rv = self.dispatch_request()
  File "E:\Program Files (x86)\Microsoft Visual Studio\Shared\Python36_64\lib\site-packages\flask\app.py", line 1935, in dispatch_request
    return self.view_functions[rule.endpoint](**req.view_args)
  File "C:\Users\Fabian\Desktop\Hopland Digital\Prosjekter\bordplassering\app\routes.py", line 255, in saveProjectWithIdentifier
    projects = db.session.query(Project).all()
NameError: name 'Project' is not defined
2020-08-23 05:53:50,052 INFO: Microblog startup [in C:\Users\Fabian\Desktop\Hopland Digital\Prosjekter\bordplassering\app\__init__.py:73]
2020-08-23 05:54:03,379 INFO: Microblog startup [in C:\Users\Fabian\Desktop\Hopland Digital\Prosjekter\bordplassering\app\__init__.py:73]
2020-08-23 05:55:12,737 INFO: Microblog startup [in C:\Users\Fabian\Desktop\Hopland Digital\Prosjekter\bordplassering\app\__init__.py:73]
2020-08-23 05:55:15,603 ERROR: Exception on /project/save/75a6fed5ce85870a [POST] [in E:\Program Files (x86)\Microsoft Visual Studio\Shared\Python36_64\lib\site-packages\flask\app.py:1891]
Traceback (most recent call last):
  File "E:\Program Files (x86)\Microsoft Visual Studio\Shared\Python36_64\lib\site-packages\sqlalchemy\engine\base.py", line 1244, in _execute_context
    cursor, statement, parameters, context
  File "E:\Program Files (x86)\Microsoft Visual Studio\Shared\Python36_64\lib\site-packages\sqlalchemy\engine\default.py", line 552, in do_execute
    cursor.execute(statement, parameters)
sqlite3.IntegrityError: UNIQUE constraint failed: projects.name

The above exception was the direct cause of the following exception:

Traceback (most recent call last):
  File "E:\Program Files (x86)\Microsoft Visual Studio\Shared\Python36_64\lib\site-packages\flask\app.py", line 2446, in wsgi_app
    response = self.full_dispatch_request()
  File "E:\Program Files (x86)\Microsoft Visual Studio\Shared\Python36_64\lib\site-packages\flask\app.py", line 1951, in full_dispatch_request
    rv = self.handle_user_exception(e)
  File "E:\Program Files (x86)\Microsoft Visual Studio\Shared\Python36_64\lib\site-packages\flask\app.py", line 1820, in handle_user_exception
    reraise(exc_type, exc_value, tb)
  File "E:\Program Files (x86)\Microsoft Visual Studio\Shared\Python36_64\lib\site-packages\flask\_compat.py", line 39, in reraise
    raise value
  File "E:\Program Files (x86)\Microsoft Visual Studio\Shared\Python36_64\lib\site-packages\flask\app.py", line 1949, in full_dispatch_request
    rv = self.dispatch_request()
  File "E:\Program Files (x86)\Microsoft Visual Studio\Shared\Python36_64\lib\site-packages\flask\app.py", line 1935, in dispatch_request
    return self.view_functions[rule.endpoint](**req.view_args)
  File "C:\Users\Fabian\Desktop\Hopland Digital\Prosjekter\bordplassering\app\routes.py", line 263, in saveProjectWithIdentifier
    db.session.commit()
  File "E:\Program Files (x86)\Microsoft Visual Studio\Shared\Python36_64\lib\site-packages\sqlalchemy\orm\scoping.py", line 162, in do
    return getattr(self.registry(), name)(*args, **kwargs)
  File "E:\Program Files (x86)\Microsoft Visual Studio\Shared\Python36_64\lib\site-packages\sqlalchemy\orm\session.py", line 1026, in commit
    self.transaction.commit()
  File "E:\Program Files (x86)\Microsoft Visual Studio\Shared\Python36_64\lib\site-packages\sqlalchemy\orm\session.py", line 493, in commit
    self._prepare_impl()
  File "E:\Program Files (x86)\Microsoft Visual Studio\Shared\Python36_64\lib\site-packages\sqlalchemy\orm\session.py", line 472, in _prepare_impl
    self.session.flush()
  File "E:\Program Files (x86)\Microsoft Visual Studio\Shared\Python36_64\lib\site-packages\sqlalchemy\orm\session.py", line 2451, in flush
    self._flush(objects)
  File "E:\Program Files (x86)\Microsoft Visual Studio\Shared\Python36_64\lib\site-packages\sqlalchemy\orm\session.py", line 2589, in _flush
    transaction.rollback(_capture_exception=True)
  File "E:\Program Files (x86)\Microsoft Visual Studio\Shared\Python36_64\lib\site-packages\sqlalchemy\util\langhelpers.py", line 68, in __exit__
    compat.reraise(exc_type, exc_value, exc_tb)
  File "E:\Program Files (x86)\Microsoft Visual Studio\Shared\Python36_64\lib\site-packages\sqlalchemy\util\compat.py", line 129, in reraise
    raise value
  File "E:\Program Files (x86)\Microsoft Visual Studio\Shared\Python36_64\lib\site-packages\sqlalchemy\orm\session.py", line 2549, in _flush
    flush_context.execute()
  File "E:\Program Files (x86)\Microsoft Visual Studio\Shared\Python36_64\lib\site-packages\sqlalchemy\orm\unitofwork.py", line 422, in execute
    rec.execute(self)
  File "E:\Program Files (x86)\Microsoft Visual Studio\Shared\Python36_64\lib\site-packages\sqlalchemy\orm\unitofwork.py", line 589, in execute
    uow,
  File "E:\Program Files (x86)\Microsoft Visual Studio\Shared\Python36_64\lib\site-packages\sqlalchemy\orm\persistence.py", line 245, in save_obj
    insert,
  File "E:\Program Files (x86)\Microsoft Visual Studio\Shared\Python36_64\lib\site-packages\sqlalchemy\orm\persistence.py", line 1120, in _emit_insert_statements
    statement, params
  File "E:\Program Files (x86)\Microsoft Visual Studio\Shared\Python36_64\lib\site-packages\sqlalchemy\engine\base.py", line 988, in execute
    return meth(self, multiparams, params)
  File "E:\Program Files (x86)\Microsoft Visual Studio\Shared\Python36_64\lib\site-packages\sqlalchemy\sql\elements.py", line 287, in _execute_on_connection
    return connection._execute_clauseelement(self, multiparams, params)
  File "E:\Program Files (x86)\Microsoft Visual Studio\Shared\Python36_64\lib\site-packages\sqlalchemy\engine\base.py", line 1107, in _execute_clauseelement
    distilled_params,
  File "E:\Program Files (x86)\Microsoft Visual Studio\Shared\Python36_64\lib\site-packages\sqlalchemy\engine\base.py", line 1248, in _execute_context
    e, statement, parameters, cursor, context
  File "E:\Program Files (x86)\Microsoft Visual Studio\Shared\Python36_64\lib\site-packages\sqlalchemy\engine\base.py", line 1466, in _handle_dbapi_exception
    util.raise_from_cause(sqlalchemy_exception, exc_info)
  File "E:\Program Files (x86)\Microsoft Visual Studio\Shared\Python36_64\lib\site-packages\sqlalchemy\util\compat.py", line 383, in raise_from_cause
    reraise(type(exception), exception, tb=exc_tb, cause=cause)
  File "E:\Program Files (x86)\Microsoft Visual Studio\Shared\Python36_64\lib\site-packages\sqlalchemy\util\compat.py", line 128, in reraise
    raise value.with_traceback(tb)
  File "E:\Program Files (x86)\Microsoft Visual Studio\Shared\Python36_64\lib\site-packages\sqlalchemy\engine\base.py", line 1244, in _execute_context
    cursor, statement, parameters, context
  File "E:\Program Files (x86)\Microsoft Visual Studio\Shared\Python36_64\lib\site-packages\sqlalchemy\engine\default.py", line 552, in do_execute
    cursor.execute(statement, parameters)
sqlalchemy.exc.IntegrityError: (sqlite3.IntegrityError) UNIQUE constraint failed: projects.name
[SQL: INSERT INTO projects (name, "projectLink", timestamp) VALUES (?, ?, ?)]
[parameters: ('', '75a6fed5ce85870a', '2020-08-23 03:55:15.603607')]
(Background on this error at: http://sqlalche.me/e/gkpj)
2020-08-23 05:58:05,722 INFO: Microblog startup [in C:\Users\Fabian\Desktop\Hopland Digital\Prosjekter\bordplassering\app\__init__.py:73]
2020-08-23 05:58:10,240 ERROR: Exception on /project/save/75a6fed5ce85870a [POST] [in E:\Program Files (x86)\Microsoft Visual Studio\Shared\Python36_64\lib\site-packages\flask\app.py:1891]
Traceback (most recent call last):
  File "E:\Program Files (x86)\Microsoft Visual Studio\Shared\Python36_64\lib\site-packages\flask\app.py", line 2446, in wsgi_app
    response = self.full_dispatch_request()
  File "E:\Program Files (x86)\Microsoft Visual Studio\Shared\Python36_64\lib\site-packages\flask\app.py", line 1951, in full_dispatch_request
    rv = self.handle_user_exception(e)
  File "E:\Program Files (x86)\Microsoft Visual Studio\Shared\Python36_64\lib\site-packages\flask\app.py", line 1820, in handle_user_exception
    reraise(exc_type, exc_value, tb)
  File "E:\Program Files (x86)\Microsoft Visual Studio\Shared\Python36_64\lib\site-packages\flask\_compat.py", line 39, in reraise
    raise value
  File "E:\Program Files (x86)\Microsoft Visual Studio\Shared\Python36_64\lib\site-packages\flask\app.py", line 1949, in full_dispatch_request
    rv = self.dispatch_request()
  File "E:\Program Files (x86)\Microsoft Visual Studio\Shared\Python36_64\lib\site-packages\flask\app.py", line 1935, in dispatch_request
    return self.view_functions[rule.endpoint](**req.view_args)
  File "C:\Users\Fabian\Desktop\Hopland Digital\Prosjekter\bordplassering\app\routes.py", line 263, in saveProjectWithIdentifier
    current_user.projects.append(Project(projectLink=str(identifier), name=jsonData["project"].name))
AttributeError: 'dict' object has no attribute 'name'
2020-08-23 05:58:35,784 INFO: Microblog startup [in C:\Users\Fabian\Desktop\Hopland Digital\Prosjekter\bordplassering\app\__init__.py:73]
